<?xml version="1.0" encoding="utf-8"?>
<!-- This URDF was automatically created by SolidWorks to URDF Exporter! Originally created by Stephen Brawner (brawner@gmail.com) 
     Commit Version: 1.5.1-0-g916b5db  Build Version: 1.5.7152.31018
     For more information, please see http://wiki.ros.org/sw_urdf_exporter -->
<robot name="gripper_base" xmlns:xacro="http://www.ros.org/wiki/xacro">>
  <xacro:include filename="$(find gripper_base)/urdf/gripper_base.gazebo"/>
  <link
    name="gripper_base_link">
    <inertial>
      <origin
        xyz="-0.0019571 1.9748E-05 0.052522"
        rpy="0 0 0" />
      <mass
        value="0.088404" />
      <inertia
        ixx="3.3349E-05"
        ixy="1.4704E-08"
        ixz="-2.4848E-07"
        iyy="2.6097E-05"
        iyz="3.2395E-09"
        izz="5.3482E-05" />
    </inertial>
    <visual>
      <origin
        xyz="0 0 0"
        rpy="0 0 0" />
      <geometry>
        <mesh
          filename="package://gripper_base/meshes/gripper_base_link.STL" />
      </geometry>
      <material
        name="">
        <color
          rgba="0.79216 0.81961 0.93333 1" />
      </material>
    </visual>
    <collision>
      <origin
        xyz="0 0 0"
        rpy="0 0 0" />
      <geometry>
        <mesh
          filename="package://gripper_base/meshes/gripper_base_link.STL" />
      </geometry>
    </collision>
  </link>
  <link
    name="l_finger_link">
    <inertial>
      <origin
        xyz="-0.0053798 -5.6205E-16 0.012857"
        rpy="0 0 0" />
      <mass
        value="0.014765" />
      <inertia
        ixx="1.6221E-06"
        ixy="-1.2909E-22"
        ixz="-3.1553E-22"
        iyy="1.5417E-06"
        iyz="1.1779E-23"
        izz="1.4779E-06" />
    </inertial>
    <visual>
      <origin
        xyz="0 0 0"
        rpy="0 0 0" />
      <geometry>
        <mesh
          filename="package://gripper_base/meshes/l_finger_link.STL" />
      </geometry>
      <material
        name="">
        <color
          rgba="0.79216 0.81961 0.93333 1" />
      </material>
    </visual>
    <collision>
      <origin
        xyz="0 0 0"
        rpy="0 0 0" />
      <geometry>
        <mesh
          filename="package://gripper_base/meshes/l_finger_link.STL" />
      </geometry>
    </collision>
  </link>

  <link name="world"/>

  <joint name="fixed123" type="fixed">
    <origin
      xyz="0 0 0"
      rpy="0 0 0" />
    <parent
      link="world" />
    <child
      link="gripper_base_link" />
    <axis
      xyz="0 0 0" />
  </joint>

  <joint
    name="l_finger_joint"
    type="continuous">
    <origin
      xyz="0 0.026 0.0565"
      rpy="0 0 0" />
    <parent
      link="gripper_base_link" />
    <child
      link="l_finger_link" />
    <axis
      xyz="0 0 -1" />
  </joint>
  <link
    name="r_finger_link">
    <inertial>
      <origin
        xyz="-0.0053798 -8.1532E-16 0.012857"
        rpy="0 0 0" />
      <mass
        value="0.014765" />
      <inertia
        ixx="1.6221E-06"
        ixy="1.8121E-21"
        ixz="-1.2879E-22"
        iyy="1.5417E-06"
        iyz="1.4405E-22"
        izz="1.4779E-06" />
    </inertial>
    <visual>
      <origin
        xyz="0 0 0"
        rpy="0 0 0" />
      <geometry>
        <mesh
          filename="package://gripper_base/meshes/r_finger_link.STL" />
      </geometry>
      <material
        name="">
        <color
          rgba="0.79216 0.81961 0.93333 1" />
      </material>
    </visual>
    <collision>
      <origin
        xyz="0 0 0"
        rpy="0 0 0" />
      <geometry>
        <mesh
          filename="package://gripper_base/meshes/r_finger_link.STL" />
      </geometry>
    </collision>
  </link>
  <joint
    name="r_finger_joint"
    type="continuous">
    <origin
      xyz="0 -0.026 0.0565"
      rpy="0 0 0" />
    <parent
      link="gripper_base_link" />
    <child
      link="r_finger_link" />
    <axis
      xyz="0 0 -1" />
  </joint>
</robot>
